Workbook
Name NativeTimeline_Date: #N/A
Name Slicer_Product: #N/A
Name Slicer_Region: #N/A
Name Slicer_Salesperson: #N/A

Sheet Analyze
A1: Date | B1: (All)
A3: Row Labels | B3: Sum of Sales | C3: Sum of Profit
A4: East | B4: 28850000 | C4: 28765605
A5: North | B5: 26320000 | C5: 26212554
A6: South | B6: 22220000 | C6: 22145162
A7: West | B7: 22835000 | C7: 22705432
A8: Grand Total | B8: 100225000 | C8: 99828753
A11: Row Labels | B11: Sum of Profit
A12: Ada | B12: 10585193
A13: Bola | B13: 15696626
A14: Chidi | B14: 17340349
A15: Efe | B15: 21246209
A16: Grace | B16: 13648860
A17: Musa | B17: 21311516
A18: Grand Total | B18: 99828753
A21: Sum of Sales | B21: Column Labels
A22: Row Labels | B22: East | C22: North | D22: South | E22: West | F22: Grand Total
A23: Headset | B23: 7280000 | C23: 1355000 | D23: 9290000 | E23: 1555000 | F23: 19480000
A24: Keyboard | B24: 85000 | C24: 6765000 | D24: 4330000 | E24: 1360000 | F24: 12540000
A25: Laptop | B25: 4155000 | C25: 6200000 | D25: 340000 | E25: 4080000 | F25: 14775000
A26: Monitor | B26: 4995000 | C26: 1510000 | D26: 3365000 | E26: 3750000 | F26: 13620000
A27: Mouse | B27: 2815000 | C27: 10020000 | D27: 140000 | E27: 8680000 | F27: 21655000
A28: Printer | B28: 9520000 | C28: 470000 | D28: 4755000 | E28: 3410000 | F28: 18155000
A29: Grand Total | B29: 28850000 | C29: 26320000 | D29: 22220000 | E29: 22835000 | F29: 100225000
A32: Row Labels | B32: Sum of Sales | C32: Sum of Profit
A33: Jan | B33: 27950000 | C33: 27871887
A34: Feb | B34: 29270000 | C34: 29161085
A35: Mar | B35: 17985000 | C35: 17924187
A36: Apr | B36: 10235000 | C36: 10169482
A37: May | B37: 8920000 | C37: 8862605
A38: Jun | B38: 5865000 | C38: 5839507
A39: Grand Total | B39: 100225000 | C39: 99828753
A76: Salesperson | B76: (All)
A78: Sum of Profit | B78: Column Labels
A79: Row Labels | B79: East | C79: North | D79: South | E79: West | F79: Grand Total
A80: Headset | B80: 7267470 | C80: 1341923 | D80: 9283850 | E80: 1537407 | F80: 19430650
A81: Keyboard | B81: 83718 | C81: 6748104 | D81: 4324700 | E81: 1333051 | F81: 12489573
A82: Laptop | B82: 4144486 | C82: 6177789 | D82: 330636 | E82: 4073218 | F82: 14726129
A83: Monitor | B83: 4959673 | C83: 1494274 | D83: 3353468 | E83: 3692138 | F83: 13499553
A84: Mouse | B84: 2800837 | C84: 9991611 | D84: 131469 | E84: 8668200 | F84: 21592117
...

Sheet Dashboard
B22: =Analyze!A23 -> Headset | C22: =Analyze!B23 -> 7280000 | D22: =Analyze!C23 -> 1355000 | E22: =Analyze!D23 -> 9290000 | F22: =Analyze!E23 -> 1555000 | G22: =Analyze!F23 -> 19480000
B23: =Analyze!A24 -> Keyboard | C23: =Analyze!B24 -> 85000 | D23: =Analyze!C24 -> 6765000 | E23: =Analyze!D24 -> 4330000 | F23: =Analyze!E24 -> 1360000 | G23: =Analyze!F24 -> 12540000
B24: =Analyze!A25 -> Laptop | C24: =Analyze!B25 -> 4155000 | D24: =Analyze!C25 -> 6200000 | E24: =Analyze!D25 -> 340000 | F24: =Analyze!E25 -> 4080000 | G24: =Analyze!F25 -> 14775000
B25: =Analyze!A26 -> Monitor | C25: =Analyze!B26 -> 4995000 | D25: =Analyze!C26 -> 1510000 | E25: =Analyze!D26 -> 3365000 | F25: =Analyze!E26 -> 3750000 | G25: =Analyze!F26 -> 13620000
B26: =Analyze!A27 -> Mouse | C26: =Analyze!B27 -> 2815000 | D26: =Analyze!C27 -> 10020000 | E26: =Analyze!D27 -> 140000 | F26: =Analyze!E27 -> 8680000 | G26: =Analyze!F27 -> 21655000
B27: =Analyze!A28 -> Printer | C27: =Analyze!B28 -> 9520000 | D27: =Analyze!C28 -> 470000 | E27: =Analyze!D28 -> 4755000 | F27: =Analyze!E28 -> 3410000 | G27: =Analyze!F28 -> 18155000
B28: =Analyze!A29 -> Grand Total | C28: =Analyze!B29 -> 28850000 | D28: =Analyze!C29 -> 26320000 | E28: =Analyze!D29 -> 22220000 | F28: =Analyze!E29 -> 22835000 | G28: =Analyze!F29 -> 100225000

Sheet HP_Nigeria_Sales_Data.xlsx
A1: Date | B1: Region | C1: Salesperson | D1: Product | E1: Cost | F1: Units Sold | G1: Unit Price | H1: Sales | I1: Profit
A2: 45710 | B2: South | C2: Ada | D2: Printer | E2: 8429 | F2: 15 | G2: 15000 | H2: =F2*G2 -> 225000 | I2: =H2-E2 -> 216571
A3: 45711 | B3: North | C3: Efe | D3: Mouse | E3: 8429 | F3: 18 | G3: 120000 | H3: =F3*G3 -> 2160000 | I3: =H3-E3 -> 2151571
A4: 45768 | B4: West | C4: Bola | D4: Monitor | E4: 8429 | F4: 10 | G4: 5000 | H4: =F4*G4 -> 50000 | I4: =H4-E4 -> 41571
A5: 45710 | B5: West | C5: Ada | D5: Headset | E5: 7779 | F5: 12 | G5: 80000 | H5: =F5*G5 -> 960000 | I5: =H5-E5 -> 952221
A6: 45768 | B6: North | C6: Chidi | D6: Monitor | E6: 7779 | F6: 10 | G6: 15000 | H6: =F6*G6 -> 150000 | I6: =H6-E6 -> 142221
A7: 45710 | B7: North | C7: Musa | D7: Laptop | E7: 7130 | F7: 12 | G7: 5000 | H7: =F7*G7 -> 60000 | I7: =H7-E7 -> 52870
A8: 45765 | B8: North | C8: Efe | D8: Printer | E8: 7130 | F8: 19 | G8: 10000 | H8: =F8*G8 -> 190000 | I8: =H8-E8 -> 182870
A9: 45708 | B9: East | C9: Bola | D9: Monitor | E9: 6480 | F9: 7 | G9: 350000 | H9: =F9*G9 -> 2450000 | I9: =H9-E9 -> 2443520
A10: 45764 | B10: North | C10: Grace | D10: Mouse | E10: 6480 | F10: 1 | G10: 350000 | H10: =F10*G10 -> 350000 | I10: =H10-E10 -> 343520
A11: 45708 | B11: East | C11: Chidi | D11: Monitor | E11: 5830 | F11: 4 | G11: 350000 | H11: =F11*G11 -> 1400000 | I11: =H11-E11 -> 1394170
A12: 45763 | B12: North | C12: Musa | D12: Keyboard | E12: 5830 | F12: 2 | G12: 10000 | H12: =F12*G12 -> 20000 | I12: =H12-E12 -> 14170
A13: 45707 | B13: West | C13: Ada | D13: Headset | E13: 5181 | F13: 11 | G13: 15000 | H13: =F13*G13 -> 165000 | I13: =H13-E13 -> 159819
... A121: 45781 | B121: East | C121: Musa | D121: Monitor | E121: 21000 | F121: 1 | G121: 5000 | H121: =F121*G121 -> 5000 | I121: =H121-E121 -> -16000
